File: InN Martins double resonans/Daten/2021.03.25-26_InN_405_nm_in txt/Gn2O3_3 x_10 s_405 nm_100%_x100 LD Zeiss Epi-Neo_2400 gr_mm_100 hole_2021_03_25_10_12_42_01.txt
#Acq. time (s)=	10
#Accumulations=	3
#Range=	Off
#Autofocus=	Off
#AutoExposure=	Off
#Spike filter=	Multiple accum.
#Delay time (s)=	0
#Binning=	1
#Readout mode=	Signal
#DeNoise=	Off
#ICS correction=	Off
#Dark correction=	Off
#Inst. Process=	Off
#Detector temperature (°C)=	-75.03
#Instrument=	T64000
#Detector=	Synapse
#Objective=	x100 LD Zeiss Epi-Neo
#Grating=	2400 gr/mm
#Filter=	100%
#Laser (nm)=	405
#Spectro (cm-¹)=	500.004
#Hole=	100
#Mono grating=	1800
#T64000 Mode=	Single
#First Slit=	-0
#Second Slit=	-0
#PreMono=	174.153
#StageXY=	PI
#X (µm)=	0
#Y (µm)=	0
#Full time(s)=	31
#Project=	InN
#Sample=	Gn2O3
#Site=
#Title=	Gn2O3_3 x_10 s_405 nm_100%_x100 LD Zeiss Epi-Neo_2400 gr_mm_100 hole_2021_03_25_10_12_10
#Remark=
#Date=	25.03.2021 10:12
#Acquired=	25.03.2021 10:12:22
101.382	12
102.177	10
102.974	11.5
103.769	11.5
104.566	10.5
105.361	12.5
106.158	11
106.953	8
107.75	10.5
108.545	10
109.342	9
110.136	10
110.933	10.5
111.728	11
112.522	12
113.319	9
114.113	9
114.908	9.5
115.704	10.5
116.498	9.5
117.293	10
118.089	8.5
118.883	11
119.677	8
120.473	7.5
121.267	10.5
122.061	10
122.855	10
123.649	9
124.445	12.5
125.239	6
126.032	7.5
126.826	12.5
127.62	10
128.413	9
129.207	9
130	11.5
130.796	12
131.589	9.5
132.382	9
133.176	10.5
133.969	10
134.762	9.5
135.555	7
136.348	10
137.141	8
137.934	11
138.727	8.5
139.518	11
140.311	8
141.104	11
141.897	7.5
142.689	9
143.482	10
144.274	11
145.067	10
145.858	9.5
146.65	10
147.442	8
148.235	13.5
149.027	11.5
149.817	11.5
150.61	10.5
151.402	8
152.192	11
152.984	9.5
153.776	12
154.566	7
155.358	10
156.15	9
156.94	13
157.731	10
158.523	9
159.313	8
160.104	11.5
160.894	10
161.685	11
162.475	10
163.266	9
164.056	9
164.847	9.5
165.636	9
166.428	9.5
167.217	9
168.008	7.5
168.797	10.5
169.588	9
170.377	9.5
171.166	11
171.957	9.5
172.746	10.5
173.535	11
174.325	10
175.114	9
175.903	9
176.693	11
177.482	8.5
178.27	9
179.059	8
179.849	11.5
180.637	9
181.426	9
182.214	9.5
183.004	8
183.792	10
184.58	11.5
185.369	9
186.157	10
186.945	9.5
187.733	10.5
188.52	10
189.308	9.5
190.098	10.5
190.886	10
191.673	8.5
192.461	10
193.249	9.5
194.036	9.5
194.824	10.5
195.611	10
196.397	9
197.184	9.5
197.971	8.5
198.758	11
199.546	9
200.333	10
201.12	8
201.907	9
202.694	9
203.479	9.5
204.266	10
205.053	8
205.839	8.5
206.626	10.5
207.411	7
208.198	9
208.984	10
209.769	9.5
210.555	12.5
211.342	10
212.128	9
212.913	9
213.699	9
214.483	11
215.269	9.5
216.056	11
216.84	9
217.626	9
218.41	8
219.196	8
219.982	10.5
220.766	10.5
221.551	7.5
222.335	8
223.121	10
223.905	10.5
224.689	9.5
225.474	8.5
226.258	12
227.043	10.5
227.827	9
228.612	7.5
229.395	10.5
230.179	8
230.964	10
231.747	11.5
232.53	9
233.315	9
234.099	8
234.882	9.5
235.665	7.5
236.45	11
237.232	10
238.015	10
238.798	11
239.581	11
240.366	11
241.148	8.5
241.931	8
242.713	11.5
243.496	9.5
244.278	8
245.061	12
245.845	11
246.627	10
247.41	10
248.192	11
248.974	10
249.756	11
250.538	8
251.32	12
252.102	11.5
252.884	11
253.666	12
254.448	14
255.228	12.5
256.01	12
256.791	11.5
257.573	11.5
258.355	13.5
259.136	14.5
259.918	14
260.697	14
261.479	15
262.26	19
263.041	16
263.822	16
264.602	20
265.383	20
266.164	23.5
266.945	21.5
267.724	25
268.505	26
269.286	28
270.065	35
270.846	37
271.625	39.5
272.405	39
273.186	45
273.965	48
274.745	54
275.524	61
276.305	61
277.083	69
277.863	74
278.644	79
279.422	90
280.2	104.5
280.981	114
281.759	112
282.539	132.5
283.317	144
284.097	151.5
284.875	175.5
285.653	184.5
286.433	191
287.211	203
287.989	217
288.768	231.5
289.546	255
290.324	267
291.103	281
291.881	298
292.659	316.5
293.436	317
294.215	335
294.993	331
295.77	341
296.547	339
297.325	364.5
298.104	374.5
298.881	371
299.658	377.5
300.435	383
301.212	394.5
301.989	413
302.766	409.5
303.543	413
304.32	412
305.097	427
305.873	425
306.65	423.5
307.427	432.5
308.203	432
308.98	437.5
309.756	433
310.533	427
311.309	454.5
312.085	483.5
312.862	501.5
313.638	504
314.412	524
315.188	545
315.964	585
316.741	634
317.516	716
318.292	817
319.066	904.5
319.842	1018
320.618	1082
321.394	1160.5
322.168	1125.5
322.943	1080.5
323.719	984
324.493	874
325.268	765
326.044	714
326.817	673
327.593	629.5
328.368	613.5
329.141	595.5
329.917	599.5
330.69	573
331.465	614
332.238	589
333.013	634
333.786	652
334.561	683.5
335.334	720
336.109	737.5
336.882	783
337.657	844
338.43	908
339.204	1008.5
339.977	1110.5
340.75	1249
341.524	1488
342.297	1680
343.069	2030.5
343.844	2467.5
344.616	3080
345.388	3764.5
346.163	4476
346.935	5133
347.707	5582
348.479	5497
349.253	5103
350.026	4412.5
350.798	3643
351.57	3020
352.342	2541
353.115	2170
353.887	1874
354.659	1690.5
355.431	1497.5
356.202	1358
356.974	1236
357.746	1116.5
358.517	1031
359.289	940
360.06	861
360.832	800.5
361.603	750.5
362.374	717.5
363.146	659
363.917	632.5
364.688	626
365.459	598
366.23	583
367.001	533.5
367.772	530.5
368.543	525
369.314	498.5
370.083	501
370.854	490
371.625	467
372.395	478.5
373.166	476
373.935	476.5
374.705	456
375.476	469.5
376.246	458
377.015	446
377.785	427
378.556	432
379.326	416
380.094	421
380.864	422
381.633	421
382.403	408
383.173	395
383.941	409
384.711	404
385.479	406.5
386.249	414
387.017	407.5
387.786	383
388.556	401
389.324	414
390.092	410.5
390.861	390
391.629	404.5
392.398	393
393.166	403
393.935	391
394.703	411
395.47	397
396.239	408
397.007	410
397.774	423
398.543	435.5
399.31	449
400.077	448
400.846	458
401.613	469.5
402.38	484
403.147	502
403.916	506.5
404.683	535.5
405.45	545
406.216	558
406.983	562
407.751	603
408.518	649
409.285	708
410.051	725
410.818	828
411.584	968.5
412.35	1144
413.117	1420
413.883	1858
414.649	2635.5
415.415	3841
416.181	5392.5
416.948	6561
417.714	6923
418.48	6317.5
419.245	4901
420.011	3515
420.777	2453
421.543	1865
422.309	1465.5
423.074	1198
423.838	1019
424.604	910
425.369	854.5
426.135	780
426.9	723
427.664	682
428.429	637.5
429.195	615
429.96	591
430.723	549.5
431.488	547.5
432.253	529.5
433.019	519.5
433.782	497
434.547	486
435.31	453
436.075	473.5
436.84	450
437.603	452.5
438.367	446.5
439.13	439.5
439.895	445
440.659	434.5
441.422	425
442.187	436
442.949	429.5
443.714	412
444.476	436
445.239	418
446.003	417
446.765	424
447.529	412
448.292	432
449.054	386
449.818	436.5
450.58	441
451.344	437
452.106	439.5
452.868	460.5
453.63	440
454.394	448
455.156	460.5
455.917	460
456.679	471.5
457.443	495
458.204	503
458.966	518.5
459.728	523.5
460.489	545
461.252	548
462.014	581
462.775	612
463.537	635.5
464.298	658
465.059	707.5
465.82	770
466.582	792
467.343	861.5
468.104	931.5
468.865	1040.5
469.626	1109
470.387	1264.5
471.147	1398
471.908	1542
472.669	1743
473.43	1966.5
474.19	2144.5
474.951	2243
475.712	2346
476.47	2404
477.231	2324
477.991	2200
478.752	2075.5
479.512	1880
480.272	1653
481.031	1520
481.791	1357
482.551	1240
483.311	1120.5
484.07	1010
484.83	921
485.589	874.5
486.348	847.5
487.107	781.5
487.867	744
488.625	686
489.385	680.5
490.143	643
490.902	628
491.662	589
492.42	560
493.179	533
493.937	528
494.696	529.5
495.454	515.5
496.213	493.5
496.971	497
497.73	493
498.487	478.5
499.246	467.5
500.004	456
500.761	453
501.52	448
502.277	441.5
503.034	444
503.793	427
504.55	422
505.307	417.5
506.065	404
506.822	428.5
507.579	406.5
508.338	388
509.094	387.5
509.851	380
510.608	369
511.364	374.5
512.122	384
512.879	376
513.635	380
514.392	374.5
515.148	365
515.904	358
516.66	356
517.417	360.5
518.173	361
518.931	354.5
519.687	345
520.443	354
521.199	364.5
521.954	349
522.71	356.5
523.464	347
524.22	356.5
524.976	366
525.731	365
526.487	345
527.243	351.5
527.998	344
528.754	353
529.509	346
530.263	359.5
531.018	341
531.773	351.5
532.528	351
533.284	347
534.037	345
534.792	356.5
535.547	349.5
536.302	361
537.055	354.5
537.81	350.5
538.565	350
539.318	342
540.073	346
540.828	353
541.58	347
542.335	355
543.088	337
543.842	371
544.595	347
545.35	354.5
546.104	344
546.857	359.5
547.611	346
548.363	330
549.116	355
549.87	353.5
550.622	355
551.376	356
552.128	354.5
552.882	368
553.635	361
554.387	367
555.14	357
555.892	351
556.644	359
557.398	372.5
558.15	369
558.902	363
559.654	360
560.407	375
561.159	368.5
561.91	354
562.662	353.5
563.413	363
564.167	363
564.918	371
565.669	346
566.421	356
567.172	375
567.923	370
568.674	376.5
569.426	363.5
570.177	368
570.93	365
571.681	376
572.432	369
573.182	371.5
573.933	369
574.682	390
575.433	383.5
576.184	375.5
576.935	364.5
577.685	365.5
578.436	374
579.186	366
579.937	371.5
580.687	380.5
581.436	367.5
582.186	371.5
582.937	359
583.687	368
584.437	374.5
585.186	369
585.936	375
586.686	368
587.436	375
588.184	366
588.934	365
589.684	384.5
590.432	372.5
591.182	378
591.931	372
592.679	365
593.429	370
594.177	365.5
594.926	387.5
595.674	366.5
596.424	385
597.173	383.5
597.921	376.5
598.67	349
599.417	384.5
600.165	388
600.914	389.5
601.662	395
602.411	388.5
603.158	390
603.907	401.5
604.654	400
605.401	402.5
606.15	408
606.897	399
607.644	412
608.393	381
609.14	411
609.887	418
610.633	415.5
611.382	416
612.129	416.5
612.875	434.5
613.622	429.5
614.369	434
615.117	430
615.863	444
616.61	446.5
617.356	461
618.103	459.5
618.849	463
619.595	487
620.341	496
621.088	519
621.834	539.5
622.58	565
623.326	614
624.072	635
624.818	707.5
625.564	778.5
626.31	887.5
627.055	1014
627.801	1163
628.547	1343
629.292	1503.5
630.038	1581.5
630.784	1617.5
631.529	1560.5
632.273	1450
633.018	1284
633.764	1141
634.509	967
635.254	876
635.998	801
636.743	733.5
637.488	677
638.232	627.5
638.977	609
639.722	582
640.465	563
641.21	573
641.955	541
642.698	553
643.442	532
644.187	539
644.93	552
645.675	550.5
646.418	566
647.162	578.5
647.905	614
648.649	653
649.392	723.5
650.136	804
650.879	933
651.623	1068
652.366	1222.5
653.108	1265
653.852	1226
654.595	1169
655.339	1175
656.081	1174
656.823	1285
657.567	1357
658.309	1380
659.051	1398.5
659.793	1341
660.537	1268
661.279	1124
662.021	995
662.762	883.5
663.506	805.5
664.248	717.5
664.989	675
665.731	629
666.473	566
667.214	561.5
667.956	493
668.699	505
669.44	486.5
670.182	481.5
670.923	475.5
671.664	457.5
672.406	435
673.147	407
673.888	433
674.629	417
675.37	418
676.111	410
676.852	398.5
677.593	383
678.332	383
679.073	383
679.814	386.5
680.554	400
681.295	383.5
682.036	382.5
682.774	381
683.515	383
684.256	387.5
684.996	372
685.736	374
686.475	361
687.215	383.5
687.956	377
688.694	379.5
689.434	369
690.174	380.5
690.913	369.5
691.653	355
692.393	367
693.131	361
693.871	365.5
694.609	356
695.349	369.5
696.087	365
696.826	372
697.566	357
698.304	368.5
699.042	377.5
699.781	381
700.519	367
701.259	362
701.996	374.5
702.736	374.5
703.473	365.5
704.211	372
704.95	387
705.687	367.5
706.425	372
707.164	395.5
707.901	381
708.638	378
709.377	378
710.114	379
710.852	407
711.589	388
712.327	375
713.064	392
713.801	404.5
714.538	397.5
715.275	423.5
716.012	399
716.749	419.5
717.487	413.5
718.224	409.5
718.96	431
719.697	410
720.433	422
721.17	413
721.906	419
722.643	437
723.379	424.5
724.115	420.5
724.851	426
725.588	428.5
726.324	437.5
727.058	433.5
727.794	435
728.53	418
729.266	436.5
730.002	436
730.738	437.5
731.474	453
732.208	443
732.944	440
733.679	441.5
734.415	447
735.149	457
735.884	445
736.62	452
737.355	468
738.089	482
738.825	481.5
739.56	488.5
740.293	488
741.029	456
741.762	476
742.497	497
743.232	518
743.966	540
744.701	554.5
745.434	553
746.169	576
746.902	589.5
747.637	601.5
748.37	633
749.105	651
749.838	682
750.571	671
751.305	745
752.038	775
752.773	814.5
753.505	893
754.238	917
754.972	987.5
755.705	1061.5
756.438	1155.5
757.172	1259
757.904	1395
758.637	1534
759.369	1706.5
760.101	1897.5
760.835	2149
761.568	2446
762.3	2781
763.032	3178.5
763.764	3545
764.496	3954
765.23	4345.5
765.962	4548
766.694	4600
767.426	4592.5
768.158	4374.5
768.889	4018
769.621	3678
770.353	3252
771.084	2934
771.816	2592.5
772.548	2321
773.279	2066
774.011	1843.5
774.742	1693
775.474	1493
776.203	1402
776.934	1294
777.666	1170
778.397	1124
779.128	1042.5
779.859	959
780.589	916
781.32	887.5
782.051	830.5
782.781	772
783.512	729
784.242	730
784.972	715
785.703	681.5
786.432	659
787.163	651
787.893	607
788.622	599
789.353	592.5
790.081	565
790.812	552
791.542	547.5
792.271	514
793.001	540.5
793.73	541
794.46	510.5
795.189	497.5
795.919	491.5
796.647	490
797.377	505
798.105	494
798.834	486.5
799.563	479.5
800.292	470
801.021	472.5
801.749	470.5
802.477	472
803.207	473
803.935	458
804.663	457
805.391	468
806.12	462
806.848	445
807.576	456.5
808.303	455
809.033	455.5
809.76	461
810.488	454
811.215	453
811.943	447.5
812.67	452
813.397	454
814.125	465.5
814.854	461.5
815.581	454
816.308	469
817.035	442
817.762	457
818.489	437
819.216	460
819.943	441
820.67	458.5
821.397	446
822.122	449
822.849	440
823.575	440
824.302	441
825.029	444
825.755	439.5
826.482	442
827.207	440
827.933	438.5
828.659	435.5
829.386	411
830.112	422
830.837	420
831.563	435
832.289	427
833.013	425
833.74	418
834.466	411.5
835.19	383
835.916	399
836.642	401.5
837.366	411.5
838.092	396.5
838.816	416
839.542	395
840.266	394.5
840.991	379.5
841.715	392.5
842.441	390.5
843.164	399
843.89	378.5
844.614	386
845.339	381.5
846.063	383
846.788	381.5
847.511	376.5
848.235	383.5
848.96	385
849.683	388.5
850.407	379
851.132	379
851.855	381.5
852.578	398
853.301	393.5
854.026	381.5
854.749	375
855.472	367
856.195	391.5
856.918	366
857.643	376
858.366	388.5
859.089	387
859.811	379
860.534	368.5
861.257	376.5
861.979	396.5
862.702	383.5
863.425	372
864.147	370
864.87	380
865.592	385
866.314	376
867.037	383
867.759	376
868.481	368
869.204	390.5
869.926	382
870.648	380
871.37	392.5
872.092	381
872.812	392
873.534	383
874.256	379
874.978	374.5
875.7	386.5
876.42	386.5
877.141	386.5