File: InN Martins double resonans/Daten/26.03.txt/txt/Ga2O3_2 x_10 s_405 nm_100%_x100 LD Zeiss Epi-Neo_2400 gr_mm_100 hole_2021_03_26_12_52_26_01.txt
#Acq. time (s)=	10
#Accumulations=	2
#Range=	Off
#Autofocus=	Off
#AutoExposure=	Off
#Spike filter=	Multiple accum.
#Delay time (s)=	0
#Binning=	1
#Readout mode=	Signal
#DeNoise=	Off
#ICS correction=	Off
#Dark correction=	Off
#Inst. Process=	Off
#Detector temperature (°C)=	-75.03
#Instrument=	T64000
#Detector=	Synapse
#Objective=	x100 LD Zeiss Epi-Neo
#Grating=	2400 gr/mm
#Filter=	100%
#Laser (nm)=	405
#Spectro (cm-¹)=	700.01
#Hole=	100
#Mono grating=	1800
#T64000 Mode=	Single
#First Slit=	-0
#Second Slit=	-0
#PreMono=	174.153
#StageXY=	PI
#X (µm)=	0
#Y (µm)=	0
#Full time(s)=	21
#Project=	InN
#Sample=	Ga2O3
#Site=
#Title=	Ga2O3_2 x_10 s_405 nm_100%_x100 LD Zeiss Epi-Neo_2400 gr_mm_100 hole_2021_03_26_12_52_05
#Remark=
#Date=	26.03.2021 12:52
#Acquired=	26.03.2021 12:52:16
410.143	363
410.156	368
410.169	379
410.182	381
410.195	392
410.208	408
410.221	388
410.235	438
410.248	461
410.261	491
410.274	562
410.287	625
410.3	698
410.313	798
410.326	876
410.34	978
410.353	962
410.366	944
410.379	898
410.392	834
410.405	752
410.418	653
410.431	585
410.444	563
410.458	542
410.471	521
410.484	513
410.497	490
410.51	500
410.523	501
410.536	525
410.549	510
410.562	556
410.576	548
410.589	575
410.602	576
410.615	637
410.628	691
410.641	728
410.654	784
410.667	878
410.68	982
410.693	1133
410.707	1354
410.72	1582
410.733	2006
410.746	2454
410.759	3031
410.772	3539
410.785	3999
410.798	4183
410.811	4171
410.824	3777
410.837	3315
410.851	2803
410.864	2355
410.877	2033
410.89	1738
410.903	1520
410.916	1334
410.929	1229
410.942	1132
410.955	1015
410.968	925
410.982	843
410.995	777
411.008	725
411.021	679
411.034	598
411.047	550
411.06	549
411.073	527
411.086	491
411.099	478
411.112	448
411.126	471
411.139	435
411.152	429
411.165	424
411.178	419
411.191	402
411.204	411
411.217	404
411.23	394
411.243	385
411.256	385
411.269	373
411.283	372
411.296	363
411.309	343
411.322	320
411.335	355
411.348	324
411.361	338
411.374	324
411.387	333
411.4	320
411.413	338
411.426	338
411.44	345
411.453	313
411.466	330
411.479	314
411.492	318
411.505	332
411.518	336
411.531	311
411.544	323
411.557	317
411.57	316
411.583	338
411.596	335
411.609	349
411.623	348
411.636	340
411.649	357
411.662	349
411.675	372
411.688	368
411.701	385
411.714	380
411.727	406
411.74	425
411.753	425
411.766	432
411.779	448
411.792	478
411.806	495
411.819	503
411.832	567
411.845	588
411.858	656
411.871	791
411.884	916
411.897	1132
411.91	1447
411.923	1960
411.936	2785
411.949	4018
411.962	5194
411.975	5763
411.988	5645
412.001	4843
412.014	3670
412.028	2643
412.041	1920
412.054	1502
412.067	1215
412.08	992
412.093	900
412.106	783
412.119	704
412.132	683
412.145	642
412.158	596
412.171	567
412.184	534
412.197	513
412.21	464
412.223	460
412.236	444
412.25	431
412.263	417
412.276	406
412.289	415
412.302	397
412.315	372
412.328	370
412.341	383
412.354	356
412.367	336
412.38	334
412.393	360
412.406	344
412.419	330
412.432	346
412.445	362
412.458	365
412.471	361
412.484	352
412.497	365
412.51	343
412.523	363
412.537	359
412.55	370
412.563	357
412.576	390
412.589	364
412.602	381
412.615	408
412.628	395
412.641	390
412.654	393
412.667	419
412.68	432
412.693	435
412.706	470
412.719	472
412.732	505
412.745	528
412.758	538
412.771	558
412.784	595
412.797	655
412.81	687
412.823	764
412.836	829
412.849	927
412.862	1014
412.875	1100
412.889	1247
412.902	1414
412.915	1601
412.928	1785
412.941	1958
412.954	2081
412.967	2202
412.98	2211
412.993	2209
413.006	2111
413.019	1925
413.032	1750
413.045	1573
413.058	1433
413.071	1268
413.084	1156
413.097	1045
413.11	956
413.123	850
413.136	794
413.149	773
413.162	694
413.175	650
413.188	641
413.201	586
413.214	589
413.227	550
413.24	551
413.253	517
413.266	491
413.279	468
413.292	454
413.305	448
413.318	423
413.331	432
413.344	420
413.357	403
413.37	385
413.383	358
413.396	385
413.409	361
413.422	368
413.435	361
413.448	345
413.461	354
413.474	342
413.487	322
413.5	330
413.513	348
413.526	329
413.539	335
413.553	296
413.566	314
413.579	315
413.592	316
413.605	296
413.618	301
413.631	306
413.644	291
413.657	301
413.67	306
413.683	288
413.696	301
413.709	291
413.722	291
413.735	287
413.748	285
413.761	270
413.774	281
413.787	261
413.8	275
413.813	261
413.826	277
413.839	267
413.852	286
413.865	280
413.878	290
413.891	270
413.904	269
413.917	273
413.93	258
413.943	264
413.956	269
413.969	279
413.982	268
413.995	277
414.008	275
414.021	277
414.034	274
414.047	275
414.06	273
414.073	276
414.086	288
414.099	278
414.111	277
414.124	264
414.137	276
414.15	272
414.163	280
414.176	271
414.189	271
414.202	282
414.215	274
414.228	269
414.241	278
414.254	272
414.267	282
414.28	278
414.293	281
414.306	274
414.319	299
414.332	289
414.345	280
414.358	272
414.371	288
414.384	270
414.397	293
414.41	298
414.423	282
414.436	277
414.449	291
414.462	287
414.475	284
414.488	268
414.501	292
414.514	285
414.527	287
414.54	293
414.553	286
414.566	296
414.579	279
414.592	291
414.605	300
414.618	288
414.631	283
414.644	287
414.657	292
414.67	300
414.683	296
414.696	294
414.709	299
414.722	282
414.735	285
414.747	292
414.76	285
414.773	292
414.786	284
414.799	309
414.812	305
414.825	287
414.838	287
414.851	292
414.864	284
414.877	296
414.89	282
414.903	309
414.916	276
414.929	278
414.942	292
414.955	278
414.968	281
414.981	295
414.994	288
415.007	295
415.02	277
415.033	295
415.046	279
415.059	294
415.072	285
415.085	304
415.098	300
415.11	304
415.123	288
415.136	310
415.149	304
415.162	319
415.175	304
415.188	317
415.201	314
415.214	301
415.227	307
415.24	323
415.253	325
415.266	340
415.279	318
415.292	324
415.305	324
415.318	333
415.331	333
415.344	339
415.357	363
415.37	353
415.382	361
415.395	379
415.408	393
415.421	376
415.434	386
415.447	395
415.46	414
415.473	425
415.486	488
415.499	488
415.512	503
415.525	577
415.538	628
415.551	711
415.564	793
415.577	940
415.59	1050
415.603	1208
415.615	1332
415.628	1355
415.641	1342
415.654	1279
415.667	1140
415.68	975
415.693	894
415.706	772
415.719	703
415.732	625
415.745	570
415.758	569
415.771	530
415.784	494
415.797	472
415.809	440
415.822	446
415.835	453
415.848	439
415.861	438
415.874	413
415.887	461
415.9	432
415.913	463
415.926	488
415.939	526
415.952	558
415.965	616
415.978	720
415.991	844
416.003	917
416.016	973
416.029	967
416.042	902
416.055	864
416.068	880
416.081	890
416.094	916
416.107	955
416.12	992
416.133	923
416.146	839
416.159	775
416.171	704
416.184	630
416.197	574
416.21	558
416.223	494
416.236	442
416.249	452
416.262	430
416.275	408
416.288	361
416.301	367
416.314	366
416.326	368
416.339	356
416.352	332
416.365	346
416.378	349
416.391	317
416.404	309
416.417	312
416.43	316
416.443	293
416.456	309
416.469	274
416.481	289
416.494	298
416.507	288
416.52	292
416.533	285
416.546	290
416.559	282
416.572	277
416.585	278
416.598	274
416.611	286
416.623	290
416.636	288
416.649	280
416.662	272
416.675	266
416.688	275
416.701	265
416.714	276
416.727	277
416.74	270
416.752	267
416.765	257
416.778	283
416.791	275
416.804	273
416.817	292
416.83	281
416.843	279
416.856	272
416.869	288
416.881	268
416.894	285
416.907	267
416.92	284
416.933	280
416.946	279
416.959	287
416.972	290
416.985	278
416.997	291
417.01	302
417.023	288
417.036	296
417.049	293
417.062	290
417.075	307
417.088	301
417.101	314
417.113	296
417.126	297
417.139	292
417.152	305
417.165	312
417.178	314
417.191	327
417.204	303
417.217	309
417.229	304
417.242	312
417.255	312
417.268	304
417.281	327
417.294	304
417.307	322
417.32	307
417.333	319
417.345	321
417.358	315
417.371	318
417.384	323
417.397	320
417.41	308
417.423	304
417.436	314
417.448	315
417.461	330
417.474	332
417.487	317
417.5	325
417.513	333
417.526	327
417.539	323
417.551	341
417.564	342
417.577	323
417.59	364
417.603	341
417.616	356
417.629	366
417.642	386
417.654	385
417.667	387
417.68	418
417.693	417
417.706	411
417.719	433
417.732	462
417.744	487
417.757	503
417.77	509
417.783	546
417.796	581
417.809	611
417.822	672
417.835	696
417.847	753
417.86	854
417.873	927
417.886	1031
417.899	1155
417.912	1275
417.925	1478
417.937	1621
417.95	1827
417.963	1964
417.976	2121
417.989	2129
418.002	2172
418.015	2142
418.027	2000
418.04	1863
418.053	1688
418.066	1506
418.079	1375
418.092	1220
418.105	1136
418.117	1005
418.13	948
418.143	833
418.156	796
418.169	748
418.182	711
418.195	659
418.207	592
418.22	604
418.233	559
418.246	518
418.259	493
418.272	488
418.284	472
418.297	462
418.31	442
418.323	419
418.336	416
418.349	407
418.362	402
418.374	382
418.387	383
418.4	366
418.413	371
418.426	367
418.439	376
418.451	349
418.464	332
418.477	347
418.49	348
418.503	347
418.516	359
418.528	328
418.541	339
418.554	341
418.567	332
418.58	321
418.593	314
418.605	312
418.618	337
418.631	324
418.644	312
418.657	312
418.67	315
418.682	316
418.695	313
418.708	305
418.721	329
418.734	323
418.747	324
418.759	325
418.772	315
418.785	321
418.798	326
418.811	312
418.824	331
418.836	317
418.849	323
418.862	318
418.875	322
418.888	325
418.901	319
418.913	309
418.926	325
418.939	324
418.952	291
418.965	316
418.978	302
418.99	307
419.003	311
419.016	326
419.029	314
419.042	328
419.054	308
419.067	318
419.08	312
419.093	317
419.106	313
419.119	314
419.131	296
419.144	315
419.157	306
419.17	306
419.183	302
419.195	305
419.208	293
419.221	300
419.234	300
419.247	284
419.26	300
419.272	288
419.285	290
419.298	276
419.311	298
419.324	284
419.336	286
419.349	281
419.362	283
419.375	293
419.388	279
419.4	287
419.413	272
419.426	288
419.439	267
419.452	276
419.465	277
419.477	292
419.49	272
419.503	273
419.516	273
419.529	282
419.541	273
419.554	283
419.567	269
419.58	265
419.593	286
419.605	263
419.618	287
419.631	276
419.644	288
419.657	279
419.669	277
419.682	276
419.695	283
419.708	293
419.721	279
419.733	270
419.746	289
419.759	294
419.772	283
419.784	277
419.797	277
419.81	297
419.823	282
419.836	274
419.848	273
419.861	280
419.874	285
419.887	282
419.9	292
419.912	288
419.925	292
419.938	286
419.951	286
419.964	288
419.976	291
419.989	275
420.002	288
420.015	291
420.027	281
420.04	278
420.053	274
420.066	278
420.079	289
420.091	291
420.104	290
420.117	287
420.13	284
420.143	277
420.155	300
420.168	289
420.181	298
420.194	288
420.206	281
420.219	296
420.232	290
420.245	267
420.258	281
420.27	302
420.283	282
420.296	273
420.309	291
420.321	290
420.334	281
420.347	282
420.36	288
420.373	286
420.385	270
420.398	256
420.411	274
420.424	289
420.436	293
420.449	283
420.462	282
420.475	279
420.487	285
420.5	274
420.513	263
420.526	270
420.539	272
420.551	268
420.564	273
420.577	271
420.59	274
420.602	270
420.615	279
420.628	262
420.641	271
420.653	269
420.666	277
420.679	277
420.692	280
420.704	260
420.717	280
420.73	267
420.743	270
420.755	275
420.768	277
420.781	279
420.794	259
420.807	274
420.819	267
420.832	278
420.845	262
420.858	281
420.87	260
420.883	254
420.896	275
420.909	265
420.921	272
420.934	270
420.947	266
420.96	266
420.972	267
420.985	268
420.998	278
421.011	263
421.023	271
421.036	265
421.049	270
421.062	262
421.074	261
421.087	281
421.1	260
421.113	262
421.125	273
421.138	254
421.151	265
421.164	268
421.176	256
421.189	271
421.202	272
421.215	267
421.227	261
421.24	255
421.253	279
421.266	268
421.278	258
421.291	265
421.304	253
421.316	259
421.329	273
421.342	269
421.355	273
421.367	266
421.38	255
421.393	264
421.406	261
421.418	272
421.431	263
421.444	267
421.457	266
421.469	268
421.482	247
421.495	260
421.507	267
421.52	264
421.533	269
421.546	256
421.558	255
421.571	271
421.584	270
421.597	269
421.609	261
421.622	263
421.635	257
421.647	242
421.66	254
421.673	270
421.686	262
421.698	276
421.711	267
421.724	255
421.737	257
421.749	262
421.762	267
421.775	256
421.787	264
421.8	266
421.813	262
421.826	264
421.838	258
421.851	267
421.864	250
421.876	265
421.889	258
421.902	267
421.915	264
421.927	280
421.94	265
421.953	254
421.965	274
421.978	278
421.991	280
422.004	269
422.016	252
422.029	264
422.042	257
422.054	276
422.067	270
422.08	269
422.093	260
422.105	255
422.118	271
422.131	261
422.143	268
422.156	261
422.169	261
422.182	268
422.194	281
422.207	266
422.22	260
422.232	272
422.245	268
422.258	256
422.271	263
422.283	257
422.296	265
422.309	269
422.321	266
422.334	278
422.347	271
422.359	264
422.372	261
422.385	254
422.398	278
422.41	257
422.423	266
422.436	260
422.448	265
422.461	268
422.474	262
422.486	249
422.499	269
422.512	263
422.524	275
422.537	263
422.55	272
422.563	266
422.575	266
422.588	267
422.601	264
422.613	280
422.626	274
422.639	287
422.651	277
422.664	281
422.677	270
422.689	254
422.702	274
422.715	279
422.728	268
422.74	264
422.753	265
422.766	283
422.778	284
422.791	271
422.804	269
422.816	279
422.829	272
422.842	289
422.854	281
422.867	255
422.88	286
422.892	267
422.905	280
422.918	279
422.93	271
422.943	278
422.956	273
422.968	288
422.981	267
422.994	270
423.007	278
423.019	283
423.032	277
423.045	277
423.057	266
423.07	277
423.083	277
423.095	289
423.108	276
423.121	285
423.133	269
423.146	292
423.159	295
423.171	283
423.184	286
423.197	284
423.209	283
423.222	268
423.235	274
423.247	279
423.26	288
423.273	297
423.285	289
423.298	292
423.311	283
423.323	283
423.336	283